package org.folio.circulation.support.results;

import static api.support.matchers.FailureMatcher.isErrorFailureContaining;
import static java.util.concurrent.CompletableFuture.completedFuture;
import static java.util.concurrent.CompletableFuture.supplyAsync;
import static org.folio.circulation.support.results.Result.succeeded;
import static org.folio.circulation.support.results.ResultExamples.alreadyFailed;
import static org.folio.circulation.support.results.ResultExamples.conditionFailed;
import static org.folio.circulation.support.results.ResultExamples.exampleFailure;
import static org.folio.circulation.support.results.ResultExamples.somethingWentWrong;
import static org.hamcrest.CoreMatchers.is;
import static org.hamcrest.MatcherAssert.assertThat;

import java.util.concurrent.ExecutionException;

import org.junit.jupiter.api.Test;

class ResultFailAfterTests {
  @Test
  void shouldPassThroughResultWhenConditionIsFalse()
    throws ExecutionException,
    InterruptedException {

    final Result<Integer> result = succeeded(10)
      .failAfter(value -> completedFuture(succeeded(false)),
        value -> exampleFailure("Specified failure"))
      .get();

    assertThat(result.succeeded(), is(true));
    assertThat(result.value(), is(10));
  }

  @Test
  void shouldApplyFailureWhenConditionIsTrue()
    throws ExecutionException,
    InterruptedException {

    final Result<Integer> result = succeeded(10)
      .failAfter(value -> completedFuture(succeeded(true)),
        value -> exampleFailure("Specified failure"))
      .get();

    assertThat(result, isErrorFailureContaining("Specified failure"));
  }

  @Test
  void shouldFailWhenAlreadyFailed()
    throws ExecutionException,
    InterruptedException {

    final Result<Integer> result = alreadyFailed()
      .failAfter(value -> completedFuture(succeeded(false)),
        value -> exampleFailure("Specified failure"))
      .get();

    assertThat(result, isErrorFailureContaining("Already failed"));
  }

  @Test
  void shouldFailWhenConditionFailed()
    throws ExecutionException,
    InterruptedException {

    final Result<Integer> result = succeeded(10)
      .failAfter(value -> completedFuture(conditionFailed()),
        value -> exampleFailure("Specified failure"))
      .get();

    assertThat(result, isErrorFailureContaining("Condition failed"));
  }

  @Test
  void shouldFailWhenConditionFailsAsynchronously()
    throws ExecutionException,
    InterruptedException {

    final Result<Integer> result = succeeded(10)
      .failAfter(value -> supplyAsync(() -> { throw somethingWentWrong(); }),
        value -> exampleFailure("Specified failure"))
      .get();

    assertThat(result, isErrorFailureContaining("Something went wrong"));
  }

  @Test
  void shouldFailWhenCreatingFailureFails()
    throws ExecutionException,
    InterruptedException {

    final Result<Integer> result = succeeded(10)
      .failAfter(value -> completedFuture(succeeded(true)),
        value -> { throw somethingWentWrong(); })
      .get();

    assertThat(result, isErrorFailureContaining("Something went wrong"));
  }
}
